Workbook
Name Slicer_dteday: #N/A
Name Slicer_holiday: #N/A
Name Slicer_mnth: #N/A
Name Slicer_weathersit: #N/A
Name Slicer_weekday: #N/A

Sheet dataset_1
A1: instant | B1: dteday | C1: season | D1: yr | E1: mnth | F1: hr | G1: holiday | H1: weekday | I1: weathersit | J1: temp | K1: atemp | L1: hum | M1: windspeed | N1: casual | O1: registered | P1: cnt | Q1: registered
A2: 1 | B2: 40544 | C2: 1 | D2: 0 | E2: 1 | F2: 0 | G2: FALSE | H2: 6 | I2: 1 | J2: 0.24 | K2: =VLOOKUP(A2,dataset_2!B:C,2,0) -> 0.2879 | L2: =VLOOKUP(A2,dataset_2!B:D,3,0) -> 0.81 | M2: =VLOOKUP(A2,dataset_2!B:E,4,0) -> 0 | N2: =VLOOKUP(A2,dataset_2!B:F,5,0) -> 3 | O2: =VLOOKUP(A2,dataset_2!B:G,6,0) -> 13 | P2: =VLOOKUP(A2,dataset_2!B:H,7,0) -> 16 | Q2: =INDEX(dataset_2!G:G,MATCH(dataset_2!B2,dataset_1!A:A,0)) -> 13
A3: 2 | B3: 40544 | C3: 1 | D3: 0 | E3: 1 | F3: 1 | G3: FALSE | H3: 6 | I3: 1 | J3: 0.22 | K3: =VLOOKUP(A3,dataset_2!B:C,2,0) -> 0.2727 | L3: =VLOOKUP(A3,dataset_2!B:D,3,0) -> 0.8 | M3: =VLOOKUP(A3,dataset_2!B:E,4,0) -> 0 | N3: =VLOOKUP(A3,dataset_2!B:F,5,0) -> 8 | O3: =VLOOKUP(A3,dataset_2!B:G,6,0) -> 32 | P3: =VLOOKUP(A3,dataset_2!B:H,7,0) -> 40 | Q3: =INDEX(dataset_2!G:G,MATCH(dataset_2!B3,dataset_1!A:A,0)) -> 32
A4: 3 | B4: 40544 | C4: 1 | D4: 0 | E4: 1 | F4: 2 | G4: FALSE | H4: 6 | I4: 1 | J4: 0.22 | K4: =VLOOKUP(A4,dataset_2!B:C,2,0) -> 0.2727 | L4: =VLOOKUP(A4,dataset_2!B:D,3,0) -> 0.8 | M4: =VLOOKUP(A4,dataset_2!B:E,4,0) -> 0 | N4: =VLOOKUP(A4,dataset_2!B:F,5,0) -> 5 | O4: =VLOOKUP(A4,dataset_2!B:G,6,0) -> 27 | P4: =VLOOKUP(A4,dataset_2!B:H,7,0) -> 32 | Q4: =INDEX(dataset_2!G:G,MATCH(dataset_2!B4,dataset_1!A:A,0)) -> 27
A5: 4 | B5: 40544 | C5: 1 | D5: 0 | E5: 1 | F5: 3 | G5: FALSE | H5: 6 | I5: 1 | J5: 0.24 | K5: =VLOOKUP(A5,dataset_2!B:C,2,0) -> 0.2879 | L5: =VLOOKUP(A5,dataset_2!B:D,3,0) -> 0.75 | M5: =VLOOKUP(A5,dataset_2!B:E,4,0) -> 0 | N5: =VLOOKUP(A5,dataset_2!B:F,5,0) -> 3 | O5: =VLOOKUP(A5,dataset_2!B:G,6,0) -> 10 | P5: =VLOOKUP(A5,dataset_2!B:H,7,0) -> 13 | Q5: =INDEX(dataset_2!G:G,MATCH(dataset_2!B5,dataset_1!A:A,0)) -> 10
A6: 5 | B6: 40544 | C6: 1 | D6: 0 | E6: 1 | F6: 4 | G6: FALSE | H6: 6 | I6: 1 | J6: 0.24 | K6: =VLOOKUP(A6,dataset_2!B:C,2,0) -> 0.2879 | L6: =VLOOKUP(A6,dataset_2!B:D,3,0) -> 0.75 | M6: =VLOOKUP(A6,dataset_2!B:E,4,0) -> 0 | N6: =VLOOKUP(A6,dataset_2!B:F,5,0) -> 0 | O6: =VLOOKUP(A6,dataset_2!B:G,6,0) -> 1 | P6: =VLOOKUP(A6,dataset_2!B:H,7,0) -> 1 | Q6: =INDEX(dataset_2!G:G,MATCH(dataset_2!B6,dataset_1!A:A,0)) -> 1
A7: 6 | B7: 40544 | C7: 1 | D7: 0 | E7: 1 | F7: 5 | G7: FALSE | H7: 6 | I7: 2 | J7: 0.24 | K7: =VLOOKUP(A7,dataset_2!B:C,2,0) -> 0.2576 | L7: =VLOOKUP(A7,dataset_2!B:D,3,0) -> 0.75 | M7: =VLOOKUP(A7,dataset_2!B:E,4,0) -> 0.0896 | N7: =VLOOKUP(A7,dataset_2!B:F,5,0) -> 0 | O7: =VLOOKUP(A7,dataset_2!B:G,6,0) -> 1 | P7: =VLOOKUP(A7,dataset_2!B:H,7,0) -> 1 | Q7: =INDEX(dataset_2!G:G,MATCH(dataset_2!B7,dataset_1!A:A,0)) -> 1
A8: 7 | B8: 40544 | C8: 1 | D8: 0 | E8: 1 | F8: 6 | G8: FALSE | H8: 6 | I8: 1 | J8: 0.22 | K8: =VLOOKUP(A8,dataset_2!B:C,2,0) -> 0.2727 | L8: =VLOOKUP(A8,dataset_2!B:D,3,0) -> 0.8 | M8: =VLOOKUP(A8,dataset_2!B:E,4,0) -> 0 | N8: =VLOOKUP(A8,dataset_2!B:F,5,0) -> 2 | O8: =VLOOKUP(A8,dataset_2!B:G,6,0) -> 0 | P8: =VLOOKUP(A8,dataset_2!B:H,7,0) -> 2 | Q8: =INDEX(dataset_2!G:G,MATCH(dataset_2!B8,dataset_1!A:A,0)) -> 0
A9: 8 | B9: 40544 | C9: 1 | D9: 0 | E9: 1 | F9: 7 | G9: FALSE | H9: 6 | I9: 1 | J9: 0.2 | K9: =VLOOKUP(A9,dataset_2!B:C,2,0) -> 0.2576 | L9: =VLOOKUP(A9,dataset_2!B:D,3,0) -> 0.86 | M9: =VLOOKUP(A9,dataset_2!B:E,4,0) -> 0 | N9: =VLOOKUP(A9,dataset_2!B:F,5,0) -> 1 | O9: =VLOOKUP(A9,dataset_2!B:G,6,0) -> 2 | P9: =VLOOKUP(A9,dataset_2!B:H,7,0) -> 3 | Q9: =INDEX(dataset_2!G:G,MATCH(dataset_2!B9,dataset_1!A:A,0)) -> 2
A10: 9 | B10: 40544 | C10: 1 | D10: 0 | E10: 1 | F10: 8 | G10: FALSE | H10: 6 | I10: 1 | J10: 0.24 | K10: =VLOOKUP(A10,dataset_2!B:C,2,0) -> 0 | L10: =VLOOKUP(A10,dataset_2!B:D,3,0) -> 0.75 | M10: =VLOOKUP(A10,dataset_2!B:E,4,0) -> 0 | N10: =VLOOKUP(A10,dataset_2!B:F,5,0) -> 1 | O10: =VLOOKUP(A10,dataset_2!B:G,6,0) -> 7 | P10: =VLOOKUP(A10,dataset_2!B:H,7,0) -> 8 | Q10: =INDEX(dataset_2!G:G,MATCH(dataset_2!B10,dataset_1!A:A,0)) -> 7
A11: 10 | B11: 40544 | C11: 1 | D11: 0 | E11: 1 | F11: 9 | G11: FALSE | H11: 6 | I11: 1 | J11: 0.32 | K11: =VLOOKUP(A11,dataset_2!B:C,2,0) -> 0.3485 | L11: =VLOOKUP(A11,dataset_2!B:D,3,0) -> 0.76 | M11: =VLOOKUP(A11,dataset_2!B:E,4,0) -> 0 | N11: =VLOOKUP(A11,dataset_2!B:F,5,0) -> 8 | O11: =VLOOKUP(A11,dataset_2!B:G,6,0) -> 6 | P11: =VLOOKUP(A11,dataset_2!B:H,7,0) -> 14 | Q11: =INDEX(dataset_2!G:G,MATCH(dataset_2!B11,dataset_1!A:A,0)) -> 6
A12: 11 | B12: 40544 | C12: 1 | D12: 0 | E12: 1 | F12: 10 | G12: FALSE | H12: 6 | I12: 1 | J12: 0.38 | K12: =VLOOKUP(A12,dataset_2!B:C,2,0) -> 0.3939 | L12: =VLOOKUP(A12,dataset_2!B:D,3,0) -> 0.76 | M12: =VLOOKUP(A12,dataset_2!B:E,4,0) -> 0.2537 | N12: =VLOOKUP(A12,dataset_2!B:F,5,0) -> 12 | O12: =VLOOKUP(A12,dataset_2!B:G,6,0) -> 24 | P12: =VLOOKUP(A12,dataset_2!B:H,7,0) -> 36 | Q12: =INDEX(dataset_2!G:G,MATCH(dataset_2!B12,dataset_1!A:A,0)) -> 24
A13: 12 | B13: 40544 | C13: 1 | D13: 0 | E13: 1 | F13: 11 | G13: FALSE | H13: 6 | I13: 1 | J13: 0.36 | K13: =VLOOKUP(A13,dataset_2!B:C,2,0) -> 0.3333 | L13: =VLOOKUP(A13,dataset_2!B:D,3,0) -> 0.81 | M13: =VLOOKUP(A13,dataset_2!B:E,4,0) -> 0.2836 | N13: =VLOOKUP(A13,dataset_2!B:F,5,0) -> 26 | O13: =VLOOKUP(A13,dataset_2!B:G,6,0) -> 30 | P13: =VLOOKUP(A13,dataset_2!B:H,7,0) -> 56 | Q13: =INDEX(dataset_2!G:G,MATCH(dataset_2!B13,dataset_1!A:A,0)) -> 30
... A611: 610 | B611: 40571 | C611: 1 | D611: 0 | E611: 1 | F611: 15 | G611: FALSE | H611: 5 | I611: 2 | J611: 0.2 | K611: =VLOOKUP(A611,dataset_2!B:C,2,0) -> 0.2576 | L611: =VLOOKUP(A611,dataset_2!B:D,3,0) -> 0.86 | M611: =VLOOKUP(A611,dataset_2!B:E,4,0) -> 0 | N611: =VLOOKUP(A611,dataset_2!B:F,5,0) -> 1 | O611: =VLOOKUP(A611,dataset_2!B:G,6,0) -> 40 | P611: =VLOOKUP(A611,dataset_2!B:H,7,0) -> 41 | Q611: =INDEX(dataset_2!G:G,MATCH(dataset_2!B611,dataset_1!A:A,0)) -> 40

Sheet dataset_2
A1: Unnamed: 0 | B1: instant | C1: atemp | D1: hum | E1: windspeed | F1: casual | G1: registered | H1: cnt
A2: 0 | B2: 1 | C2: 0.2879 | D2: 0.81 | E2: 0 | F2: 3 | G2: 13 | H2: 16
A3: 1 | B3: 2 | C3: 0.2727 | D3: 0.8 | E3: 0 | F3: 8 | G3: 32 | H3: 40
A4: 2 | B4: 3 | C4: 0.2727 | D4: 0.8 | E4: 0 | F4: 5 | G4: 27 | H4: 32
A5: 3 | B5: 4 | C5: 0.2879 | D5: 0.75 | E5: 0 | F5: 3 | G5: 10 | H5: 13
A6: 4 | B6: 5 | C6: 0.2879 | D6: 0.75 | E6: 0 | F6: 0 | G6: 1 | H6: 1
A7: 5 | B7: 6 | C7: 0.2576 | D7: 0.75 | E7: 0.0896 | F7: 0 | G7: 1 | H7: 1
A8: 6 | B8: 7 | C8: 0.2727 | D8: 0.8 | E8: 0 | F8: 2 | G8: 0 | H8: 2
A9: 7 | B9: 8 | C9: 0.2576 | D9: 0.86 | E9: 0 | F9: 1 | G9: 2 | H9: 3
A10: 8 | B10: 9 | D10: 0.75 | E10: 0 | F10: 1 | G10: 7 | H10: 8
A11: 9 | B11: 10 | C11: 0.3485 | D11: 0.76 | E11: 0 | F11: 8 | G11: 6 | H11: 14
A12: 10 | B12: 11 | C12: 0.3939 | D12: 0.76 | E12: 0.2537 | F12: 12 | G12: 24 | H12: 36
A13: 11 | B13: 12 | C13: 0.3333 | D13: 0.81 | E13: 0.2836 | F13: 26 | G13: 30 | H13: 56
A14: 12 | B14: 13 | C14: 0.4242 | D14: 0.77 | E14: 0.2836 | F14: 29 | G14: 55 | H14: 84
A15: 13 | B15: 14 | C15: 0.4545 | D15: 0.72 | E15: 0.2985 | F15: 47 | G15: 47 | H15: 94
A16: 14 | B16: 15 | C16: 0.4545 | D16: 0.72 | E16: 0.2836 | F16: 35 | G16: 71 | H16: 106
A17: 15 | B17: 16 | C17: 0.4394 | D17: 0.77 | E17: 0.2985 | F17: 40 | G17: 70 | H17: 110
A18: 16 | B18: 17 | C18: 0.4242 | D18: 0.82 | E18: 0.2985 | F18: 41 | G18: 52 | H18: 93
A19: 17 | B19: 18 | D19: 0.82 | E19: 0.2836 | F19: 15 | G19: 52 | H19: 67
A20: 18 | B20: 19 | C20: 0.4242 | D20: 0.88 | E20: 0.2537 | F20: 9 | G20: 26 | H20: 35
A21: 19 | B21: 20 | C21: 0.4242 | D21: 0.88 | E21: 0.2537 | F21: 6 | G21: 31 | H21: 37
A22: 20 | B22: 21 | C22: 0.4091 | D22: 0.87 | E22: 0.2537 | F22: 11 | G22: 25 | H22: 36
A23: 21 | B23: 22 | C23: 0.4091 | D23: 0.87 | E23: 0.194 | F23: 3 | G23: 31 | H23: 34
A24: 22 | B24: 23 | C24: 0.4091 | D24: 0.94 | E24: 0.2239 | F24: 11 | G24: 17 | H24: 28
A25: 23 | B25: 24 | D25: 0.88 | E25: 0.2985 | F25: 15 | G25: 24 | H25: 39
A26: 24 | B26: 25 | C26: 0.4545 | D26: 0.88 | E26: 0.2985 | F26: 4 | G26: 13 | H26: 17
A27: 25 | B27: 26 | C27: 0.4394 | D27: 0.94 | E27: 0.2537 | F27: 1 | G27: 16 | H27: 17
A28: 26 | B28: 27 | C28: 0.4242 | D28: 1 | E28: 0.2836 | F28: 1 | G28: 8 | H28: 9
A29: 27 | B29: 28 | C29: 0.4545 | D29: 0.94 | E29: 0.194 | F29: 2 | G29: 4 | H29: 6
A30: 28 | B30: 29 | D30: 0.94 | E30: 0.194 | F30: 2 | G30: 1 | H30: 3
A31: 29 | B31: 30 | C31: 0.4242 | D31: 0.77 | E31: 0.2985 | F31: 0 | G31: 2 | H31: 2
A32: 30 | B32: 31 | C32: 0.4091 | D32: 0.76 | E32: 0.194 | F32: 0 | G32: 1 | H32: 1
A33: 31 | B33: 32 | C33: 0.4091 | D33: 0.71 | E33: 0.2239 | F33: 0 | G33: 8 | H33: 8
A34: 32 | B34: 33 | D34: 0.76 | E34: 0.2239 | F34: 1 | G34: 19 | H34: 20
A35: 33 | B35: 34 | C35: 0.3485 | D35: 0.81 | E35: 0.2239 | F35: 7 | G35: 46 | H35: 53
A36: 34 | B36: 35 | C36: 0.3333 | D36: 0.71 | E36: 0.2537 | F36: 16 | G36: 54 | H36: 70
A37: 35 | B37: 36 | C37: 0.3333 | D37: 0.66 | E37: 0.2985 | F37: 20 | G37: 73 | H37: 93
A38: 36 | B38: 37 | C38: 0.3485 | D38: 0.66 | E38: 0.1343 | F38: 11 | G38: 64 | H38: 75
A39: 37 | B39: 38 | D39: 0.76 | E39: 0.194 | F39: 4 | G39: 55 | H39: 59
A40: 38 | B40: 39 | C40: 0.3333 | D40: 0.81 | E40: 0.1642 | F40: 19 | G40: 55 | H40: 74
...

Sheet dataset_3
A1: instant | B1: dteday | C1: season | D1: yr | E1: mnth | F1: hr | G1: holiday | H1: weekday | I1: weathersit | J1: temp | K1: atemp | L1: hum | M1: windspeed | N1: casual | O1: registered | P1: cnt
A2: 620 | B2: 40572 | C2: 1 | D2: 0 | E2: 1 | F2: 1 | G2: FALSE | H2: 6 | I2: 1 | J2: 0.22 | K2: 0.2273 | L2: 0.64 | M2: 0.194 | N2: 0 | O2: 20 | P2: 20
A3: 621 | B3: 40572 | C3: 1 | D3: 0 | E3: 1 | F3: 2 | G3: FALSE | H3: 6 | I3: 1 | J3: 0.22 | K3: 0.2273 | L3: 0.64 | M3: 0.1642 | N3: 0 | O3: 15 | P3: 15
A4: 622 | B4: 40572 | C4: 1 | D4: 0 | E4: 1 | F4: 3 | G4: FALSE | H4: 6 | I4: 1 | J4: 0.2 | K4: 0.2121 | L4: 0.64 | M4: 0.1343 | N4: 3 | O4: 5 | P4: 8
A5: 623 | B5: 40572 | C5: 1 | D5: 0 | E5: 1 | F5: 4 | G5: FALSE | H5: 6 | I5: 1 | J5: 0.16 | K5: 0.1818 | L5: 0.69 | M5: 0.1045 | N5: 1 | O5: 2 | P5: 3
A6: 624 | B6: 40572 | C6: 1 | D6: 0 | E6: 1 | F6: 6 | G6: FALSE | H6: 6 | I6: 1 | J6: 0.16 | K6: 0.1818 | L6: 0.64 | M6: 0.1343 | N6: 0 | O6: 2 | P6: 2
A7: 625 | B7: 40572 | C7: 1 | D7: 0 | E7: 1 | F7: 7 | G7: FALSE | H7: 6 | I7: 1 | J7: 0.16 | K7: 0.1818 | L7: 0.59 | M7: 0.1045 | N7: 1 | O7: 4 | P7: 5
A8: 626 | B8: 40572 | C8: 1 | D8: 0 | E8: 1 | F8: 8 | G8: FALSE | H8: 6 | I8: 1 | J8: 0.18 | K8: 0.197 | L8: 0.55 | M8: 0.1642 | N8: 3 | O8: 31 | P8: 34
A9: 627 | B9: 40572 | C9: 1 | D9: 0 | E9: 1 | F9: 9 | G9: FALSE | H9: 6 | I9: 1 | J9: 0.18 | K9: 0.2121 | L9: 0.59 | M9: 0.0896 | N9: 0 | O9: 34 | P9: 34
A10: 628 | B10: 40572 | C10: 1 | D10: 0 | E10: 1 | F10: 10 | G10: FALSE | H10: 6 | I10: 2 | J10: 0.18 | K10: 0.2121 | L10: 0.64 | M10: 0.1045 | N10: 4 | O10: 51 | P10: 55
A11: 629 | B11: 40572 | C11: 1 | D11: 0 | E11: 1 | F11: 11 | G11: FALSE | H11: 6 | I11: 2 | J11: 0.18 | K11: 0.197 | L11: 0.64 | M11: 0.1343 | N11: 4 | O11: 60 | P11: 64
A12: 630 | B12: 40572 | C12: 1 | D12: 0 | E12: 1 | F12: 12 | G12: FALSE | H12: 6 | I12: 2 | J12: 0.2 | K12: 0.197 | L12: 0.59 | M12: 0.194 | N12: 12 | O12: 66 | P12: 78
A13: 631 | B13: 40572 | C13: 1 | D13: 0 | E13: 1 | F13: 13 | G13: FALSE | H13: 6 | I13: 2 | J13: 0.22 | K13: 0.2273 | L13: 0.55 | M13: 0.1642 | N13: 9 | O13: 56 | P13: 65
... A391: 619 | B391: 40572 | C391: 1 | D391: 0 | E391: 1 | F391: 0 | G391: FALSE | H391: 6 | I391: 1 | J391: 0.22 | K391: 0.197 | L391: 0.64 | M391: 0.3582 | N391: 2 | O391: 26 | P391: 28

Sheet Remove duplicate
A1: instant | B1: dteday | C1: season | D1: yr | E1: mnth | F1: hr | G1: holiday | H1: weekday | I1: weathersit | J1: temp | K1: atemp | L1: hum | M1: windspeed | N1: casual | O1: registered | P1: cnt
A2: 1 | B2: 40544 | C2: 1 | D2: 0 | E2: 1 | F2: 0 | G2: FALSE | H2: 6 | I2: 1 | J2: 0.24 | K2: =VLOOKUP(A2,dataset_2!B:C,2,0) -> 0.2879 | L2: =VLOOKUP(A2,dataset_2!B:D,3,0) -> 0.81 | M2: =VLOOKUP(A2,dataset_2!B:E,4,0) -> 0 | N2: =VLOOKUP(A2,dataset_2!B:F,5,0) -> 3 | O2: =VLOOKUP(A2,dataset_2!B:G,6,0) -> 13 | P2: =VLOOKUP(A2,dataset_2!B:H,7,0) -> 16
A3: 25 | B3: 40545 | C3: 1 | D3: 0 | E3: 1 | F3: 0 | G3: FALSE | H3: 0 | I3: 2 | J3: 0.46 | K3: =VLOOKUP(A3,dataset_2!B:C,2,0) -> 0.4545 | L3: =VLOOKUP(A3,dataset_2!B:D,3,0) -> 0.88 | M3: =VLOOKUP(A3,dataset_2!B:E,4,0) -> 0.2985 | N3: =VLOOKUP(A3,dataset_2!B:F,5,0) -> 4 | O3: =VLOOKUP(A3,dataset_2!B:G,6,0) -> 13 | P3: =VLOOKUP(A3,dataset_2!B:H,7,0) -> 17
A4: 48 | B4: 40546 | C4: 1 | D4: 0 | E4: 1 | F4: 0 | G4: FALSE | H4: 1 | I4: 1 | J4: 0.22 | K4: =VLOOKUP(A4,dataset_2!B:C,2,0) -> 0.197 | L4: =VLOOKUP(A4,dataset_2!B:D,3,0) -> 0.44 | M4: =VLOOKUP(A4,dataset_2!B:E,4,0) -> 0.3582 | N4: =VLOOKUP(A4,dataset_2!B:F,5,0) -> 0 | O4: =VLOOKUP(A4,dataset_2!B:G,6,0) -> 5 | P4: =VLOOKUP(A4,dataset_2!B:H,7,0) -> 5
A5: 70 | B5: 40547 | C5: 1 | D5: 0 | E5: 1 | F5: 0 | G5: FALSE | H5: 2 | I5: 1 | J5: 0.16 | K5: =VLOOKUP(A5,dataset_2!B:C,2,0) -> 0 | L5: =VLOOKUP(A5,dataset_2!B:D,3,0) -> 0.55 | M5: =VLOOKUP(A5,dataset_2!B:E,4,0) -> 0.1045 | N5: =VLOOKUP(A5,dataset_2!B:F,5,0) -> 0 | O5: =VLOOKUP(A5,dataset_2!B:G,6,0) -> 5 | P5: =VLOOKUP(A5,dataset_2!B:H,7,0) -> 5
A6: 93 | B6: 40548 | C6: 1 | D6: 0 | E6: 1 | F6: 0 | G6: FALSE | H6: 3 | I6: 1 | J6: 0.2 | K6: =VLOOKUP(A6,dataset_2!B:C,2,0) -> 0.2576 | L6: =VLOOKUP(A6,dataset_2!B:D,3,0) -> 0.64 | M6: =VLOOKUP(A6,dataset_2!B:E,4,0) -> 0 | N6: =VLOOKUP(A6,dataset_2!B:F,5,0) -> 0 | O6: =VLOOKUP(A6,dataset_2!B:G,6,0) -> 6 | P6: =VLOOKUP(A6,dataset_2!B:H,7,0) -> 6
A7: 116 | B7: 40549 | C7: 1 | D7: 0 | E7: 1 | F7: 0 | G7: FALSE | H7: 4 | I7: 1 | J7: 0.18 | K7: =VLOOKUP(A7,dataset_2!B:C,2,0) -> 0.2424 | L7: =VLOOKUP(A7,dataset_2!B:D,3,0) -> 0.55 | M7: =VLOOKUP(A7,dataset_2!B:E,4,0) -> 0 | N7: =VLOOKUP(A7,dataset_2!B:F,5,0) -> 0 | O7: =VLOOKUP(A7,dataset_2!B:G,6,0) -> 11 | P7: =VLOOKUP(A7,dataset_2!B:H,7,0) -> 11
A8: 139 | B8: 40550 | C8: 1 | D8: 0 | E8: 1 | F8: 0 | G8: FALSE | H8: 5 | I8: 2 | J8: 0.2 | K8: =VLOOKUP(A8,dataset_2!B:C,2,0) -> 0.197 | L8: =VLOOKUP(A8,dataset_2!B:D,3,0) -> 0.64 | M8: =VLOOKUP(A8,dataset_2!B:E,4,0) -> 0.194 | N8: =VLOOKUP(A8,dataset_2!B:F,5,0) -> 4 | O8: =VLOOKUP(A8,dataset_2!B:G,6,0) -> 13 | P8: =VLOOKUP(A8,dataset_2!B:H,7,0) -> 17
A9: 162 | B9: 40551 | C9: 1 | D9: 0 | E9: 1 | F9: 0 | G9: FALSE | H9: 6 | I9: 2 | J9: 0.18 | K9: =VLOOKUP(A9,dataset_2!B:C,2,0) -> 0.197 | L9: =VLOOKUP(A9,dataset_2!B:D,3,0) -> 0.51 | M9: =VLOOKUP(A9,dataset_2!B:E,4,0) -> 0.1642 | N9: =VLOOKUP(A9,dataset_2!B:F,5,0) -> 1 | O9: =VLOOKUP(A9,dataset_2!B:G,6,0) -> 24 | P9: =VLOOKUP(A9,dataset_2!B:H,7,0) -> 25
A10: 186 | B10: 40552 | C10: 1 | D10: 0 | E10: 1 | F10: 0 | G10: FALSE | H10: 0 | I10: 1 | J10: 0.1 | K10: =VLOOKUP(A10,dataset_2!B:C,2,0) -> 0.0758 | L10: =VLOOKUP(A10,dataset_2!B:D,3,0) -> 0.42 | M10: =VLOOKUP(A10,dataset_2!B:E,4,0) -> 0.3881 | N10: =VLOOKUP(A10,dataset_2!B:F,5,0) -> 1 | O10: =VLOOKUP(A10,dataset_2!B:G,6,0) -> 24 | P10: =VLOOKUP(A10,dataset_2!B:H,7,0) -> 25
A11: 210 | B11: 40553 | C11: 1 | D11: 0 | E11: 1 | F11: 0 | G11: FALSE | H11: 1 | I11: 1 | J11: 0.12 | K11: =VLOOKUP(A11,dataset_2!B:C,2,0) -> 0.1212 | L11: =VLOOKUP(A11,dataset_2!B:D,3,0) -> 0.5 | M11: =VLOOKUP(A11,dataset_2!B:E,4,0) -> 0.2836 | N11: =VLOOKUP(A11,dataset_2!B:F,5,0) -> 2 | O11: =VLOOKUP(A11,dataset_2!B:G,6,0) -> 3 | P11: =VLOOKUP(A11,dataset_2!B:H,7,0) -> 5
A12: 234 | B12: 40554 | C12: 1 | D12: 0 | E12: 1 | F12: 0 | G12: FALSE | H12: 2 | I12: 1 | J12: 0.14 | K12: =VLOOKUP(A12,dataset_2!B:C,2,0) -> 0.1667 | L12: =VLOOKUP(A12,dataset_2!B:D,3,0) -> 0.59 | M12: =VLOOKUP(A12,dataset_2!B:E,4,0) -> 0.1045 | N12: =VLOOKUP(A12,dataset_2!B:F,5,0) -> 2 | O12: =VLOOKUP(A12,dataset_2!B:G,6,0) -> 10 | P12: =VLOOKUP(A12,dataset_2!B:H,7,0) -> 12
A13: 256 | B13: 40555 | C13: 1 | D13: 0 | E13: 1 | F13: 0 | G13: FALSE | H13: 3 | I13: 2 | J13: 0.16 | K13: =VLOOKUP(A13,dataset_2!B:C,2,0) -> 0.197 | L13: =VLOOKUP(A13,dataset_2!B:D,3,0) -> 0.86 | M13: =VLOOKUP(A13,dataset_2!B:E,4,0) -> 0.0896 | N13: =VLOOKUP(A13,dataset_2!B:F,5,0) -> 0 | O13: =VLOOKUP(A13,dataset_2!B:G,6,0) -> 7 | P13: =VLOOKUP(A13,dataset_2!B:H,7,0) -> 7
... A29: 596 | B29: 40571 | C29: 1 | D29: 0 | E29: 1 | F29: 0 | G29: FALSE | H29: 5 | I29: 2 | J29: 0.2 | K29: =VLOOKUP(A29,dataset_2!B:C,2,0) -> 0.2121 | L29: =VLOOKUP(A29,dataset_2!B:D,3,0) -> 0.75 | M29: =VLOOKUP(A29,dataset_2!B:E,4,0) -> 0.1343 | N29: =VLOOKUP(A29,dataset_2!B:F,5,0) -> 0 | O29: =VLOOKUP(A29,dataset_2!B:G,6,0) -> 9 | P29: =VLOOKUP(A29,dataset_2!B:H,7,0) -> 9

Sheet Pivot & slicers
A1: Demand by Time | G1: Demand by Weather | S1: Demand by User Type
G2: Average of cnt | K2: Values | T2: Values
A3: Sum of cnt | G3: weathersit | H3: Total | J3: weekday | K3: Average of atemp | L3: Sum of casual | M3: Average of hum | N3: Sum of registered | O3: Average of windspeed | S3: weekday | T3: Sum of registered | U3: Sum of casual
A4: weekday | B4: Total | G4: 1 | H4: 55.562327 | J4: 1 | K4: 0.19749145 | L4: 726 | M4: 0.55290598 | N4: 4183 | O4: 0.22477778 | S4: 1 | T4: 4183 | U4: 726
A5: 1 | B5: 8121 | G5: 2 | H5: 57.582474 | J5: 2 | K5: 0.15903419 | L5: 406 | M5: 0.51205128 | N5: 6181 | O5: 0.20181026 | S5: 2 | T5: 6181 | U5: 406
A6: 2 | B6: 8450 | G6: 3 | H6: 32.775 | J6: 3 | K6: 0.21364125 | L6: 346 | M6: 0.665125 | N6: 5147 | O6: 0.13900375 | S6: 3 | T6: 5147 | U6: 346
A7: 3 | B7: 8383 | G7: 4 | H7: 36 | J7: 4 | K7: 0.22529643 | L7: 219 | M7: 0.64404762 | N7: 4699 | O7: 0.24396905 | S7: 4 | T7: 4699 | U7: 219
A8: 4 | B8: 8049 | G8: Grand Total | H8: 54.657718 | J8: 5 | K8: 0.21346582 | L8: 224 | M8: 0.52696203 | N8: 5146 | O8: 0.18856203 | S8: 5 | T8: 5146 | U8: 224
A9: 5 | B9: 8458 | J9: 7 | K9: 0.20410504 | L9: 839 | M9: 0.57983193 | N9: 4460 | O9: 0.18236975 | S9: 7 | T9: 4460 | U9: 839
A10: 6 | B10: 9691 | J10: Grand Total | K10: 0.19946644 | L10: 2760 | M10: 0.57473154 | N10: 29816 | O10: 0.19819279 | S10: Grand Total | T10: 29816 | U10: 2760
A11: 7 | B11: 7776
A12: Grand Total | B12: 58928 | W12: weathersit | X12: Total
S13: Weekday | T13: Registered | U13: Casual | W13: 1 | X13: 61.745098
S14: 1 | T14: 6644 | U14: 1477 | W14: 2 | X14: 58.701923
S15: 2 | T15: 7916 | U15: 534 | W15: 3 | X15: 33.202381
S16: 3 | T16: 7926 | U16: 457 | W16: 4 | X16: 36
S17: 4 | T17: 7705 | U17: 344
S18: 5 | T18: 8126 | U18: 332
S19: 6 | T19: 9117 | U19: 574
S20: 7 | T20: 6549 | U20: 1227
S21: Grand Total | T21: 53983 | U21: 4945

Sheet Dashboard
A1: BIKE SHARING DEMAND ANALYSIS
A2: Summary Report: Methods, Findings & Recommendations
A3: Generated: May 21, 2026
A5: 1. EXECUTIVE SUMMARY
A6: This report analyzes bike sharing demand data to identify usage patterns, weather impacts, and user behavior.
A7: The dataset contains 1,009 hourly records from January-February 2011, tracking casual and registered riders.
A8: Key metrics analyzed include: temperature, humidity, wind speed, weather conditions, and ridership counts.
A10: 2. DATA SOURCES & METHODOLOGY
A11: Data Source | B11: Records | C11: Columns | D11: Purpose | E11: Processing Applied
A12: dataset_1 | B12: 611 | C12: 17 | D12: Primary hourly bike demand data | E12: VLOOKUP, INDEX formulas
A13: dataset_2 | B13: 611 | C13: 8 | D13: Weather & environmental factors | E13: Data validation
A14: dataset_3 | B14: 391 | C14: 16 | D14: Extended time period data | E14: Date formatting
A15: Append1 (Power Query) | B15: 1009 | C15: 21 | D15: Consolidated dataset | E15: Appended via Power Query
A16: Remove duplicate | B16: 28 | C16: 16 | D16: Deduplicated daily records | E16: Duplicate removal
A18: 3. ANALYSIS METHODS APPLIED
A19: Method Category | B19: Technique | C19: Column/Application | D19: Status
A20: Data Transformation | B20: Sorting | C20: instant column | D20: Done
A21: Data Transformation | B21: Date Formatting | C21: dteday column | D21: Done
A22: Formula Functions | B22: YEAR() formula | C22: yr column | D22: Done
A23: Formula Functions | B23: MONTH() formula | C23: mnth column | D23: Done
A24: Formula Functions | B24: IF condition | C24: holiday column | D24: Done
A25: Formula Functions | B25: WEEKDAY() formula | C25: weekday column | D25: Done
A26: Lookup Functions | B26: VLOOKUP | C26: dataset_1 | D26: Done
A27: Lookup Functions | B27: INDEX function | C27: dataset_1 | D27: Done
A28: Conditional Functions | B28: COUNTIF | C28: Count column | D28: Done
A29: Conditional Functions | B29: SUMIF | C29: Append1 sheet | D29: Done
A30: Text Functions | B30: LEFT / RIGHT / MID | C30: Count column | D30: Done
... A40: Pivot Analysis | B40: PivotTables with Slicers | C40: Demand analysis | D40: Done
A42: 4. KEY FINDINGS
A44: 4.1 Demand by Day of Week
A45: Weekday | B45: Total Rides | C45: Interpretation
A46: Sunday (1) | B46: 8121 | C46: Moderate weekend usage
A47: Monday (2) | B47: 8450 | C47: Strong weekday commute
A48: Tuesday (3) | B48: 8383 | C48: Consistent weekday usage
A49: Wednesday (4) | B49: 8049 | C49: Slight mid-week dip
A50: Thursday (5) | B50: 8458 | C50: Peak weekday usage
A51: Friday (6) | B51: 9691 | C51: Highest demand day
A52: Saturday (7) | B52: 7776 | C52: Lower weekend usage
A53: TOTAL | B53: 58928 | C53: Grand Total
A55: 4.2 Weather Impact on Demand
...

Sheet Pivot with gropuing & aggretati
G1: aggregrating by Sum of Casual & registered | K1: aggregrating byCount of Casual & registered | O1: aggregrating by average of Casual & registered
A3: Sum of weathersit
A4: Months (dteday) | B4: dteday | C4: Total | H4: Values | L4: Values | P4: Values
A5: Jan | B5: 40544 | C5: 38 | G5: weekday | H5: Sum of casual | I5: Sum of Average count | K5: weekday | L5: Count of casual | M5: Count of registered | O5: weekday | P5: Average of casual | Q5: Average of registered
B6: 40545 | C6: 45 | G6: 1 | H6: 1477 | I6: 9.0060976 | K6: 1 | L6: 164 | M6: 164 | O6: 1 | P6: 9.0060976 | Q6: 40.512195
B7: 40546 | C7: 22 | G7: 2 | H7: 534 | I7: 1.7919463 | K7: 2 | L7: 149 | M7: 149 | O7: 2 | P7: 3.5838926 | Q7: 53.127517
B8: 40547 | C8: 24 | G8: 3 | H8: 457 | I8: 1.1994751 | K8: 3 | L8: 127 | M8: 127 | O8: 3 | P8: 3.5984252 | Q8: 62.409449
B9: 40548 | C9: 23 | G9: 4 | H9: 344 | I9: 0.65648855 | K9: 4 | L9: 131 | M9: 131 | O9: 4 | P9: 2.6259542 | Q9: 58.816794
B10: 40549 | C10: 31 | G10: 5 | H10: 332 | I10: 0.5312 | K10: 5 | L10: 125 | M10: 125 | O10: 5 | P10: 2.656 | Q10: 65.008
B11: 40550 | C11: 39 | G11: 6 | H11: 574 | I11: 0.65525114 | K11: 6 | L11: 146 | M11: 146 | O11: 6 | P11: 3.9315068 | Q11: 62.445205
B12: 40551 | C12: 41 | G12: 7 | H12: 1227 | I12: 1.0496151 | K12: 7 | L12: 167 | M12: 167 | O12: 7 | P12: 7.3473054 | Q12: 39.215569
B13: 40552 | C13: 24 | G13: Grand Total | H13: 4945 | I13: 1.2249195 | K13: Grand Total | L13: 1009 | M13: 1009 | O13: Grand Total | P13: 4.900892 | Q13: 53.501487
B14: 40553 | C14: 32
B15: 40554 | C15: 48
B16: 40555 | C16: 24
B17: 40556 | C17: 26
B18: 40557 | C18: 25
B19: 40558 | C19: 36
B20: 40559 | C20: 29
B21: 40560 | C21: 52
B22: 40561 | C22: 24
B23: 40562 | C23: 38
B24: 40563 | C24: 37
B25: 40564 | C25: 31
... B35: 40574 | C35: 43
A36: Jan Total | C36: 1026
A37: Feb | C37: 466
A38: Grand Total | C38: 1492

Sheet Append1 through Powerquery
J1: =SUM(Append1[temp]) -> 208 | K1: =SUBTOTAL(9,Append1[atemp]) -> 211.7021 | L1: =AVERAGE(Append1[hum]) -> 0.58361744 | Q1: 40544 | S1: 7
A2: instant | B2: dteday | C2: season | D2: yr | E2: mnth | F2: hr | G2: holiday | H2: weekday | I2: weathersit | J2: temp | K2: atemp | L2: hum | M2: windspeed | N2: casual | O2: registered | P2: cnt | Q2: Count IF | R2: Count IF2 | S2: Sumif( | T2: STDV | U2: Correl
A3: 1 | B3: 40544 | C3: 1 | D3: =YEAR(Append1[[#This Row],[dteday]]) -> 2011 | E3: =MONTH(Append1[[#This Row],[dteday]]) -> 1 | F3: =HOUR(Append1[[#This Row],[dteday]]) -> 0 | G3: {=_xlfn.IFS(Append1[[#This Row],[weekday]]=6,"True",Append1[[#This Row],[weekday]]=0,"True",TRUE,"False")} -> False | H3: =WEEKDAY(Append1[[#This Row],[dteday]],1) -> 7 | I3: 1 | J3: 0.24 | K3: 0.2879 | L3: 0.81 | M3: 0 | N3: 3 | O3: 13 | P3: 16 | Q3: =COUNTIF(Append1[dteday],Q1) -> 24 | R3: =COUNTIF(Append1[casual],">15") -> 66 | S3: =SUMIF(Append1[weekday],S1,Append1[cnt]) -> 7776 | T3: =STDEV(Append1[[#All],[atemp]:[windspeed]]) -> 0.22737173 | U3: =CORREL(Append1[[#All],[temp]],Append1[[#All],[atemp]]) -> 0.83636671
A4: 2 | B4: 40544 | C4: 1 | D4: =YEAR(Append1[[#This Row],[dteday]]) -> 2011 | E4: 1 | F4: =HOUR(Append1[[#This Row],[dteday]]) -> 0 | G4: =IF(OR(Append1[[#This Row],[weekday]]=6,Append1[[#This Row],[weekday]]=0),"True","False") -> False | H4: =WEEKDAY(Append1[[#This Row],[dteday]],1) -> 7 | I4: 1 | J4: 0.22 | K4: 0.2727 | L4: 0.8 | M4: 0 | N4: 8 | O4: 32 | P4: 40
A5: 3 | B5: 40544 | C5: 1 | D5: =YEAR(Append1[[#This Row],[dteday]]) -> 2011 | E5: 1 | F5: =HOUR(Append1[[#This Row],[dteday]]) -> 0 | G5: {=_xlfn.IFS(Append1[[#This Row],[weekday]]=6,"True",Append1[[#This Row],[weekday]]=0,"True",TRUE,"False")} -> False | H5: =WEEKDAY(Append1[[#This Row],[dteday]],1) -> 7 | I5: 1 | J5: 0.22 | K5: 0.2727 | L5: 0.8 | M5: 0 | N5: 5 | O5: 27 | P5: 32 | Q5: Left
A6: 4 | B6: 40544 | C6: 1 | D6: =YEAR(Append1[[#This Row],[dteday]]) -> 2011 | E6: 1 | F6: =HOUR(Append1[[#This Row],[dteday]]) -> 0 | G6: {=_xlfn.IFS(Append1[[#This Row],[weekday]]=6,"True",Append1[[#This Row],[weekday]]=0,"True",TRUE,"False")} -> False | H6: =WEEKDAY(Append1[[#This Row],[dteday]],1) -> 7 | I6: 1 | J6: 0.24 | K6: 0.2879 | L6: 0.75 | M6: 0 | N6: 3 | O6: 10 | P6: 13 | Q6: =LEFT(Append1[[#This Row],[holiday]],2) -> Fa
A7: 5 | B7: 40544 | C7: 1 | D7: =YEAR(Append1[[#This Row],[dteday]]) -> 2011 | E7: 1 | F7: =HOUR(Append1[[#This Row],[dteday]]) -> 0 | G7: {=_xlfn.IFS(Append1[[#This Row],[weekday]]=6,"True",Append1[[#This Row],[weekday]]=0,"True",TRUE,"False")} -> False | H7: =WEEKDAY(Append1[[#This Row],[dteday]],1) -> 7 | I7: 1 | J7: 0.24 | K7: 0.2879 | L7: 0.75 | M7: 0 | N7: 0 | O7: 1 | P7: 1 | Q7: =LEFT(Append1[[#This Row],[holiday]],2) -> Fa
A8: 6 | B8: 40544 | C8: 1 | D8: =YEAR(Append1[[#This Row],[dteday]]) -> 2011 | E8: 1 | F8: =HOUR(Append1[[#This Row],[dteday]]) -> 0 | G8: {=_xlfn.IFS(Append1[[#This Row],[weekday]]=6,"True",Append1[[#This Row],[weekday]]=0,"True",TRUE,"False")} -> False | H8: =WEEKDAY(Append1[[#This Row],[dteday]],1) -> 7 | I8: 2 | J8: 0.24 | K8: 0.2576 | L8: 0.75 | M8: 0.0896 | N8: 0 | O8: 1 | P8: 1 | Q8: =LEFT(Append1[[#This Row],[holiday]],2) -> Fa
A9: 7 | B9: 40544 | C9: 1 | D9: =YEAR(Append1[[#This Row],[dteday]]) -> 2011 | E9: 1 | F9: =HOUR(Append1[[#This Row],[dteday]]) -> 0 | G9: {=_xlfn.IFS(Append1[[#This Row],[weekday]]=6,"True",Append1[[#This Row],[weekday]]=0,"True",TRUE,"False")} -> False | H9: =WEEKDAY(Append1[[#This Row],[dteday]],1) -> 7 | I9: 1 | J9: 0.22 | K9: 0.2727 | L9: 0.8 | M9: 0 | N9: 2 | O9: 0 | P9: 2 | Q9: =LEFT(Append1[[#This Row],[holiday]],2) -> Fa
A10: 8 | B10: 40544 | C10: 1 | D10: =YEAR(Append1[[#This Row],[dteday]]) -> 2011 | E10: 1 | F10: =HOUR(Append1[[#This Row],[dteday]]) -> 0 | G10: {=_xlfn.IFS(Append1[[#This Row],[weekday]]=6,"True",Append1[[#This Row],[weekday]]=0,"True",TRUE,"False")} -> False | H10: =WEEKDAY(Append1[[#This Row],[dteday]],1) -> 7 | I10: 1 | J10: 0.2 | K10: 0.2576 | L10: 0.86 | M10: 0 | N10: 1 | O10: 2 | P10: 3
A11: 9 | B11: 40544 | C11: 1 | D11: =YEAR(Append1[[#This Row],[dteday]]) -> 2011 | E11: 1 | F11: =HOUR(Append1[[#This Row],[dteday]]) -> 0 | G11: {=_xlfn.IFS(Append1[[#This Row],[weekday]]=6,"True",Append1[[#This Row],[weekday]]=0,"True",TRUE,"False")} -> False | H11: =WEEKDAY(Append1[[#This Row],[dteday]],1) -> 7 | I11: 1 | J11: 0.24 | K11: 0 | L11: 0.75 | M11: 0 | N11: 1 | O11: 7 | P11: 8
A12: 10 | B12: 40544 | C12: 1 | D12: =YEAR(Append1[[#This Row],[dteday]]) -> 2011 | E12: 1 | F12: =HOUR(Append1[[#This Row],[dteday]]) -> 0 | G12: {=_xlfn.IFS(Append1[[#This Row],[weekday]]=6,"True",Append1[[#This Row],[weekday]]=0,"True",TRUE,"False")} -> False | H12: =WEEKDAY(Append1[[#This Row],[dteday]],1) -> 7 | I12: 1 | J12: 0.32 | K12: 0.3485 | L12: 0.76 | M12: 0 | N12: 8 | O12: 6 | P12: 14 | Q12: Mid
A13: 11 | B13: 40544 | C13: 1 | D13: =YEAR(Append1[[#This Row],[dteday]]) -> 2011 | E13: 1 | F13: =HOUR(Append1[[#This Row],[dteday]]) -> 0 | G13: {=_xlfn.IFS(Append1[[#This Row],[weekday]]=6,"True",Append1[[#This Row],[weekday]]=0,"True",TRUE,"False")} -> False | H13: =WEEKDAY(Append1[[#This Row],[dteday]],1) -> 7 | I13: 1 | J13: 0.38 | K13: 0.3939 | L13: 0.76 | M13: 0.2537 | N13: 12 | O13: 24 | P13: 36 | Q13: =MID(Append1[[#This Row],[holiday]],2,2) -> al
A14: 12 | B14: 40544 | C14: 1 | D14: =YEAR(Append1[[#This Row],[dteday]]) -> 2011 | E14: 1 | F14: =HOUR(Append1[[#This Row],[dteday]]) -> 0 | G14: {=_xlfn.IFS(Append1[[#This Row],[weekday]]=6,"True",Append1[[#This Row],[weekday]]=0,"True",TRUE,"False")} -> False | H14: =WEEKDAY(Append1[[#This Row],[dteday]],1) -> 7 | I14: 1 | J14: 0.36 | K14: 0.3333 | L14: 0.81 | M14: 0.2836 | N14: 26 | O14: 30 | P14: 56 | Q14: =MID(Append1[[#This Row],[holiday]],2,2) -> al
A15: 13 | B15: 40544 | C15: 1 | D15: =YEAR(Append1[[#This Row],[dteday]]) -> 2011 | E15: 1 | F15: =HOUR(Append1[[#This Row],[dteday]]) -> 0 | G15: {=_xlfn.IFS(Append1[[#This Row],[weekday]]=6,"True",Append1[[#This Row],[weekday]]=0,"True",TRUE,"False")} -> False | H15: =WEEKDAY(Append1[[#This Row],[dteday]],1) -> 7 | I15: 1 | J15: 0.42 | K15: 0.4242 | L15: 0.77 | M15: 0.2836 | N15: 29 | O15: 55 | P15: 84 | Q15: =MID(Append1[[#This Row],[holiday]],2,2) -> al
A16: 14 | B16: 40544 | C16: 1 | D16: =YEAR(Append1[[#This Row],[dteday]]) -> 2011 | E16: 1 | F16: =HOUR(Append1[[#This Row],[dteday]]) -> 0 | G16: {=_xlfn.IFS(Append1[[#This Row],[weekday]]=6,"True",Append1[[#This Row],[weekday]]=0,"True",TRUE,"False")} -> False | H16: =WEEKDAY(Append1[[#This Row],[dteday]],1) -> 7 | I16: 2 | J16: 0.46 | K16: 0.4545 | L16: 0.72 | M16: 0.2985 | N16: 47 | O16: 47 | P16: 94 | Q16: =MID(Append1[[#This Row],[holiday]],2,2) -> al
A17: 15 | B17: 40544 | C17: 1 | D17: =YEAR(Append1[[#This Row],[dteday]]) -> 2011 | E17: 1 | F17: =HOUR(Append1[[#This Row],[dteday]]) -> 0 | G17: {=_xlfn.IFS(Append1[[#This Row],[weekday]]=6,"True",Append1[[#This Row],[weekday]]=0,"True",TRUE,"False")} -> False | H17: =WEEKDAY(Append1[[#This Row],[dteday]],1) -> 7 | I17: 2 | J17: 0.46 | K17: 0.4545 | L17: 0.72 | M17: 0.2836 | N17: 35 | O17: 71 | P17: 106 | Q17: =MID(Append1[[#This Row],[holiday]],2,2) -> al
A18: 16 | B18: 40544 | C18: 1 | D18: =YEAR(Append1[[#This Row],[dteday]]) -> 2011 | E18: 1 | F18: =HOUR(Append1[[#This Row],[dteday]]) -> 0 | G18: {=_xlfn.IFS(Append1[[#This Row],[weekday]]=6,"True",Append1[[#This Row],[weekday]]=0,"True",TRUE,"False")} -> False | H18: =WEEKDAY(Append1[[#This Row],[dteday]],1) -> 7 | I18: 2 | J18: 0.44 | K18: 0.4394 | L18: 0.77 | M18: 0.2985 | N18: 40 | O18: 70 | P18: 110 | Q18: =MID(Append1[[#This Row],[holiday]],2,2) -> al
A19: 17 | B19: 40544 | C19: 1 | D19: =YEAR(Append1[[#This Row],[dteday]]) -> 2011 | E19: 1 | F19: =HOUR(Append1[[#This Row],[dteday]]) -> 0 | G19: {=_xlfn.IFS(Append1[[#This Row],[weekday]]=6,"True",Append1[[#This Row],[weekday]]=0,"True",TRUE,"False")} -> False | H19: =WEEKDAY(Append1[[#This Row],[dteday]],1) -> 7 | I19: 2 | J19: 0.42 | K19: 0.4242 | L19: 0.82 | M19: 0.2985 | N19: 41 | O19: 52 | P19: 93
A20: 18 | B20: 40544 | C20: 1 | D20: =YEAR(Append1[[#This Row],[dteday]]) -> 2011 | E20: 1 | F20: =HOUR(Append1[[#This Row],[dteday]]) -> 0 | G20: {=_xlfn.IFS(Append1[[#This Row],[weekday]]=6,"True",Append1[[#This Row],[weekday]]=0,"True",TRUE,"False")} -> False | H20: =WEEKDAY(Append1[[#This Row],[dteday]],1) -> 7 | I20: 2 | J20: 0.44 | K20: 0 | L20: 0.82 | M20: 0.2836 | N20: 15 | O20: 52 | P20: 67
A21: 19 | B21: 40544 | C21: 1 | D21: =YEAR(Append1[[#This Row],[dteday]]) -> 2011 | E21: 1 | F21: =HOUR(Append1[[#This Row],[dteday]]) -> 0 | G21: {=_xlfn.IFS(Append1[[#This Row],[weekday]]=6,"True",Append1[[#This Row],[weekday]]=0,"True",TRUE,"False")} -> False | H21: =WEEKDAY(Append1[[#This Row],[dteday]],1) -> 7 | I21: 3 | J21: 0.42 | K21: 0.4242 | L21: 0.88 | M21: 0.2537 | N21: 9 | O21: 26 | P21: 35
A22: 20 | B22: 40544 | C22: 1 | D22: =YEAR(Append1[[#This Row],[dteday]]) -> 2011 | E22: 1 | F22: =HOUR(Append1[[#This Row],[dteday]]) -> 0 | G22: {=_xlfn.IFS(Append1[[#This Row],[weekday]]=6,"True",Append1[[#This Row],[weekday]]=0,"True",TRUE,"False")} -> False | H22: =WEEKDAY(Append1[[#This Row],[dteday]],1) -> 7 | I22: 3 | J22: 0.42 | K22: 0.4242 | L22: 0.88 | M22: 0.2537 | N22: 6 | O22: 31 | P22: 37 | Q22: Right
A23: 21 | B23: 40544 | C23: 1 | D23: =YEAR(Append1[[#This Row],[dteday]]) -> 2011 | E23: 1 | F23: =HOUR(Append1[[#This Row],[dteday]]) -> 0 | G23: {=_xlfn.IFS(Append1[[#This Row],[weekday]]=6,"True",Append1[[#This Row],[weekday]]=0,"True",TRUE,"False")} -> False | H23: =WEEKDAY(Append1[[#This Row],[dteday]],1) -> 7 | I23: 2 | J23: 0.4 | K23: 0.4091 | L23: 0.87 | M23: 0.2537 | N23: 11 | O23: 25 | P23: 36 | Q23: =RIGHT(Append1[[#This Row],[holiday]],3) -> lse
A24: 22 | B24: 40544 | C24: 1 | D24: =YEAR(Append1[[#This Row],[dteday]]) -> 2011 | E24: 1 | F24: =HOUR(Append1[[#This Row],[dteday]]) -> 0 | G24: {=_xlfn.IFS(Append1[[#This Row],[weekday]]=6,"True",Append1[[#This Row],[weekday]]=0,"True",TRUE,"False")} -> False | H24: =WEEKDAY(Append1[[#This Row],[dteday]],1) -> 7 | I24: 2 | J24: 0.4 | K24: 0.4091 | L24: 0.87 | M24: 0.194 | N24: 3 | O24: 31 | P24: 34 | Q24: =RIGHT(Append1[[#This Row],[holiday]],3) -> lse
A25: 23 | B25: 40544 | C25: 1 | D25: =YEAR(Append1[[#This Row],[dteday]]) -> 2011 | E25: 1 | F25: =HOUR(Append1[[#This Row],[dteday]]) -> 0 | G25: {=_xlfn.IFS(Append1[[#This Row],[weekday]]=6,"True",Append1[[#This Row],[weekday]]=0,"True",TRUE,"False")} -> False | H25: =WEEKDAY(Append1[[#This Row],[dteday]],1) -> 7 | I25: 2 | J25: 0.4 | K25: 0.4091 | L25: 0.94 | M25: 0.2239 | N25: 11 | O25: 17 | P25: 28 | Q25: =RIGHT(Append1[[#This Row],[holiday]],3) -> lse
A26: 24 | B26: 40544 | C26: 1 | D26: =YEAR(Append1[[#This Row],[dteday]]) -> 2011 | E26: 1 | F26: =HOUR(Append1[[#This Row],[dteday]]) -> 0 | G26: {=_xlfn.IFS(Append1[[#This Row],[weekday]]=6,"True",Append1[[#This Row],[weekday]]=0,"True",TRUE,"False")} -> False | H26: =WEEKDAY(Append1[[#This Row],[dteday]],1) -> 7 | I26: 2 | J26: 0.46 | K26: 0 | L26: 0.88 | M26: 0.2985 | N26: 15 | O26: 24 | P26: 39 | Q26: =RIGHT(Append1[[#This Row],[holiday]],3) -> lse
A27: 25 | B27: 40545 | C27: 1 | D27: =YEAR(Append1[[#This Row],[dteday]]) -> 2011 | E27: 1 | F27: =HOUR(Append1[[#This Row],[dteday]]) -> 0 | G27: {=_xlfn.IFS(Append1[[#This Row],[weekday]]=6,"True",Append1[[#This Row],[weekday]]=0,"True",TRUE,"False")} -> False | H27: =WEEKDAY(Append1[[#This Row],[dteday]],1) -> 1 | I27: 2 | J27: 0.46 | K27: 0.4545 | L27: 0.88 | M27: 0.2985 | N27: 4 | O27: 13 | P27: 17
A28: 26 | B28: 40545 | C28: 1 | D28: =YEAR(Append1[[#This Row],[dteday]]) -> 2011 | E28: 1 | F28: =HOUR(Append1[[#This Row],[dteday]]) -> 0 | G28: {=_xlfn.IFS(Append1[[#This Row],[weekday]]=6,"True",Append1[[#This Row],[weekday]]=0,"True",TRUE,"False")} -> False | H28: =WEEKDAY(Append1[[#This Row],[dteday]],1) -> 1 | I28: 2 | J28: 0.44 | K28: 0.4394 | L28: 0.94 | M28: 0.2537 | N28: 1 | O28: 16 | P28: 17
A29: 27 | B29: 40545 | C29: 1 | D29: =YEAR(Append1[[#This Row],[dteday]]) -> 2011 | E29: 1 | F29: =HOUR(Append1[[#This Row],[dteday]]) -> 0 | G29: {=_xlfn.IFS(Append1[[#This Row],[weekday]]=6,"True",Append1[[#This Row],[weekday]]=0,"True",TRUE,"False")} -> False | H29: =WEEKDAY(Append1[[#This Row],[dteday]],1) -> 1 | I29: 2 | J29: 0.42 | K29: 0.4242 | L29: 1 | M29: 0.2836 | N29: 1 | O29: 8 | P29: 9
A30: 28 | B30: 40545 | C30: 1 | D30: =YEAR(Append1[[#This Row],[dteday]]) -> 2011 | E30: 1 | F30: =HOUR(Append1[[#This Row],[dteday]]) -> 0 | G30: {=_xlfn.IFS(Append1[[#This Row],[weekday]]=6,"True",Append1[[#This Row],[weekday]]=0,"True",TRUE,"False")} -> False | H30: =WEEKDAY(Append1[[#This Row],[dteday]],1) -> 1 | I30: 2 | J30: 0.46 | K30: 0.4545 | L30: 0.94 | M30: 0.194 | N30: 2 | O30: 4 | P30: 6
A31: 29 | B31: 40545 | C31: 1 | D31: =YEAR(Append1[[#This Row],[dteday]]) -> 2011 | E31: 1 | F31: =HOUR(Append1[[#This Row],[dteday]]) -> 0 | G31: {=_xlfn.IFS(Append1[[#This Row],[weekday]]=6,"True",Append1[[#This Row],[weekday]]=0,"True",TRUE,"False")} -> False | H31: =WEEKDAY(Append1[[#This Row],[dteday]],1) -> 1 | I31: 2 | J31: 0.46 | K31: 0 | L31: 0.94 | M31: 0.194 | N31: 2 | O31: 1 | P31: 3
A32: 30 | B32: 40545 | C32: 1 | D32: =YEAR(Append1[[#This Row],[dteday]]) -> 2011 | E32: 1 | F32: =HOUR(Append1[[#This Row],[dteday]]) -> 0 | G32: {=_xlfn.IFS(Append1[[#This Row],[weekday]]=6,"True",Append1[[#This Row],[weekday]]=0,"True",TRUE,"False")} -> False | H32: =WEEKDAY(Append1[[#This Row],[dteday]],1) -> 1 | I32: 3 | J32: 0.42 | K32: 0.4242 | L32: 0.77 | M32: 0.2985 | N32: 0 | O32: 2 | P32: 2
A33: 31 | B33: 40545 | C33: 1 | D33: =YEAR(Append1[[#This Row],[dteday]]) -> 2011 | E33: 1 | F33: =HOUR(Append1[[#This Row],[dteday]]) -> 0 | G33: {=_xlfn.IFS(Append1[[#This Row],[weekday]]=6,"True",Append1[[#This Row],[weekday]]=0,"True",TRUE,"False")} -> False | H33: =WEEKDAY(Append1[[#This Row],[dteday]],1) -> 1 | I33: 2 | J33: 0.4 | K33: 0.4091 | L33: 0.76 | M33: 0.194 | N33: 0 | O33: 1 | P33: 1
A34: 32 | B34: 40545 | C34: 1 | D34: =YEAR(Append1[[#This Row],[dteday]]) -> 2011 | E34: 1 | F34: =HOUR(Append1[[#This Row],[dteday]]) -> 0 | G34: {=_xlfn.IFS(Append1[[#This Row],[weekday]]=6,"True",Append1[[#This Row],[weekday]]=0,"True",TRUE,"False")} -> False | H34: =WEEKDAY(Append1[[#This Row],[dteday]],1) -> 1 | I34: 3 | J34: 0.4 | K34: 0.4091 | L34: 0.71 | M34: 0.2239 | N34: 0 | O34: 8 | P34: 8
A35: 33 | B35: 40545 | C35: 1 | D35: =YEAR(Append1[[#This Row],[dteday]]) -> 2011 | E35: 1 | F35: =HOUR(Append1[[#This Row],[dteday]]) -> 0 | G35: {=_xlfn.IFS(Append1[[#This Row],[weekday]]=6,"True",Append1[[#This Row],[weekday]]=0,"True",TRUE,"False")} -> False | H35: =WEEKDAY(Append1[[#This Row],[dteday]],1) -> 1 | I35: 2 | J35: 0.38 | K35: 0 | L35: 0.76 | M35: 0.2239 | N35: 1 | O35: 19 | P35: 20
A36: 34 | B36: 40545 | C36: 1 | D36: =YEAR(Append1[[#This Row],[dteday]]) -> 2011 | E36: 1 | F36: =HOUR(Append1[[#This Row],[dteday]]) -> 0 | G36: {=_xlfn.IFS(Append1[[#This Row],[weekday]]=6,"True",Append1[[#This Row],[weekday]]=0,"True",TRUE,"False")} -> False | H36: =WEEKDAY(Append1[[#This Row],[dteday]],1) -> 1 | I36: 2 | J36: 0.36 | K36: 0.3485 | L36: 0.81 | M36: 0.2239 | N36: 7 | O36: 46 | P36: 53
A37: 35 | B37: 40545 | C37: 1 | D37: =YEAR(Append1[[#This Row],[dteday]]) -> 2011 | E37: 1 | F37: =HOUR(Append1[[#This Row],[dteday]]) -> 0 | G37: {=_xlfn.IFS(Append1[[#This Row],[weekday]]=6,"True",Append1[[#This Row],[weekday]]=0,"True",TRUE,"False")} -> False | H37: =WEEKDAY(Append1[[#This Row],[dteday]],1) -> 1 | I37: 2 | J37: 0.36 | K37: 0.3333 | L37: 0.71 | M37: 0.2537 | N37: 16 | O37: 54 | P37: 70
A38: 36 | B38: 40545 | C38: 1 | D38: =YEAR(Append1[[#This Row],[dteday]]) -> 2011 | E38: 1 | F38: =HOUR(Append1[[#This Row],[dteday]]) -> 0 | G38: {=_xlfn.IFS(Append1[[#This Row],[weekday]]=6,"True",Append1[[#This Row],[weekday]]=0,"True",TRUE,"False")} -> False | H38: =WEEKDAY(Append1[[#This Row],[dteday]],1) -> 1 | I38: 2 | J38: 0.36 | K38: 0.3333 | L38: 0.66 | M38: 0.2985 | N38: 20 | O38: 73 | P38: 93
... A1008: 997 | B1008: 40588 | C1008: 1 | D1008: =YEAR(Append1[[#This Row],[dteday]]) -> 2011 | E1008: 2 | F1008: =HOUR(Append1[[#This Row],[dteday]]) -> 0 | G1008: {=_xlfn.IFS(Append1[[#This Row],[weekday]]=6,"True",Append1[[#This Row],[weekday]]=0,"True",TRUE,"False")} -> False | H1008: =WEEKDAY(Append1[[#This Row],[dteday]],1) -> 2 | I1008: 1 | J1008: 0.32 | K1008: 0.303 | L1008: 0.53 | M1008: 0.2836 | N1008: 0 | O1008: 2 | P1008: 2
A1009: 998 | B1009: 40588 | C1009: 1 | D1009: =YEAR(Append1[[#This Row],[dteday]]) -> 2011 | E1009: 2 | F1009: =HOUR(Append1[[#This Row],[dteday]]) -> 0 | G1009: =IF(OR(Append1[[#This Row],[weekday]]=6,Append1[[#This Row],[weekday]]=0),"True","False") -> False | H1009: =WEEKDAY(Append1[[#This Row],[dteday]],1) -> 2 | I1009: 1 | J1009: 0.32 | K1009: 0.303 | L1009: 0.53 | M1009: 0.2836 | N1009: 0 | O1009: 3 | P1009: 3
...

Sheet summary
C2: Status | D2: Column | E2: Sheet
B3: Sorting | C3: Done | D3: instant | E3: Append1
B4: Formatting Date | C4: Done | D4: dteday | E4: Append1
B5: Year formula | C5: Done | D5: yr | E5: Append1
B6: Month formula | C6: Done | D6: mnth | E6: Append1
B7: Date formula | C7: Done | D7: hr | E7: Append1
B8: If condition | C8: Done | D8: holiday | E8: Append1
B9: weekday formula | C9: Done | D9: weekday | E9: Append1
B10: Conditional formatting Blue colour between 0.1 to 0.2 | C10: Done | D10: temp | E10: Append1
B11: Conditional formatting Yelloow colour between 0.34 | C11: Done | D11: temp | E11: Append1
B12: Conditional formatting Pink colour between 0.38 to 0.46 | C12: Done | D12: temp | E12: Append1
B13: Sum | C13: Done | D13: temp | E13: Append1
B14: Average | C14: Done | D14: hum | E14: Append1
... B17: left / right / mid | C17: Done | D17: Count | E17: Append1
B18: Vlookup in yellow colu | C18: Done | E18: dataset_1
B19: Index in pink colu | C19: Done | E19: dataset_1
B20: Sumif | C20: Done | E20: Append1
B21: STDV | C21: Done | E21: Append1
B22: Correl | C22: Done | E22: Append1
